Workbook

Sheet DB
A1: ID | B1: 공종 | C1: 분류 | D1: 품명 | E1: 표시순서 | F1: 규격 | G1: 단위 | H1: 할증_min | I1: 할증_max | J1: 출처코드 | K1: 조항위치 | L1: 원문페이지 | M1: 적용시작 | N1: 적용종료 | O1: 정식명칭 | P1: 비고 | Q1: 태그 | R1: 중요도 | S1: 올림적용 | T1: 상태 | U1: 수정일 | V1: 검증메모
A2: CV-ETC-001 | B2: 토목, 건축 | C2: 기타재료 | D2: 레미콘 | E2: 1 | F2: 무근구조물 | G2: ㎥ | H2: 2 | I2: 2 | J2: KCS-STD | K2: 1-3-1 8. 기타재료 | L2: 78 | M2: 2026 | O2: 레디믹스트 콘크리트:무근구조물 | Q2: 콘크리트 | R2: 주요 | S2: N | T2: 검증완료 | U2: 2026-08-27 | V2: 2026년 원문 p76~79 대조 완료
A3: CV-ETC-002 | B3: 토목, 건축 | C3: 기타재료 | D3: 레미콘 | E3: 2 | F3: 철근구조물 | G3: ㎥ | H3: 1 | I3: 1 | J3: KCS-STD | K3: 1-3-1 8. 기타재료 | L3: 78 | M3: 2026 | O3: 레디믹스트 콘크리트:철근구조물(무근구조물) | Q3: 콘크리트 | R3: 주요 | S3: N | T3: 검증완료 | U3: 2026-08-27 | V3: 2026년 원문 p76~79 대조 완료
A4: CV-ETC-003 | B4: 토목, 건축 | C4: 기타재료 | D4: 레미콘 | F4: 포장용 | G4: ㎥ | H4: 4 | I4: 4 | J4: KCS-STD | K4: 1-3-1 8. 기타재료 | L4: 78 | M4: 2026 | O4: 콘크리트포장혼합물의포설 | Q4: 콘크리트 | R4: 주요 | S4: N | T4: 검증완료 | U4: 2026-08-27 | V4: 2026년 원문 p76~79 대조 완료
A5: CV-ETC-004 | B5: 토목, 건축 | C5: 기타재료 | D5: 아스팔트 | F5: 포장용 | G5: ton | H5: 2 | I5: 2 | J5: KCS-STD | K5: 1-3-1 8. 기타재료 | L5: 78 | M5: 2026 | O5: 아스팔트 콘크리트 포설 | R5: 주요 | S5: N | T5: 검증완료 | U5: 2026-08-27 | V5: 2026년 원문 p76~79 대조 완료
A6: CV-CON-001 | B6: 토목, 건축 | C6: 콘크리트·포장 | D6: 시멘트 | F6: 정치식(배치플랜트) | G6: kg | H6: 2 | I6: 2 | J6: KCS-STD | K6: 1-3-1 1. 콘크리트 및 포장용 재료 | L6: 76 | M6: 2026 | O6: 시멘트 | R6: 주요 | S6: N | T6: 검증완료 | U6: 2026-08-27 | V6: 2026년 원문 p76~79 대조 완료 / 원문 표기는 "정치식"/"기타" 2열. 규격의 "정치식(현장믹서)"는 원문상 "기타" 열
A7: CV-CON-002 | B7: 토목, 건축 | C7: 콘크리트·포장 | D7: 잔골재, 채움재 | F7: 정치식(배치플랜트) | G7: ㎥ | H7: 10 | I7: 10 | J7: KCS-STD | K7: 1-3-1 1. 콘크리트 및 포장용 재료 | L7: 76 | M7: 2026 | O7: 잔골재, 채움재 | R7: 기타 | S7: N | T7: 검증완료 | U7: 2026-08-27 | V7: 2026년 원문 p76~79 대조 완료 / 원문 표기는 "정치식"/"기타" 2열. 규격의 "정치식(현장믹서)"는 원문상 "기타" 열
A8: CV-CON-003 | B8: 토목, 건축 | C8: 콘크리트·포장 | D8: 굵은골재 | F8: 정치식(배치플랜트) | G8: ㎥ | H8: 3 | I8: 3 | J8: KCS-STD | K8: 1-3-1 1. 콘크리트 및 포장용 재료 | L8: 76 | M8: 2026 | O8: 굵은골재 | R8: 기타 | S8: N | T8: 검증완료 | U8: 2026-08-27 | V8: 2026년 원문 p76~79 대조 완료 / 원문 표기는 "정치식"/"기타" 2열. 규격의 "정치식(현장믹서)"는 원문상 "기타" 열
A9: CV-CON-004 | B9: 토목, 건축 | C9: 콘크리트·포장 | D9: 아스팔트 | F9: 정치식(배치플랜트) | G9: ton | H9: 2 | I9: 2 | J9: KCS-STD | K9: 1-3-1 1. 콘크리트 및 포장용 재료 | L9: 76 | M9: 2026 | O9: 아스팔트 | R9: 주요 | S9: N | T9: 검증완료 | U9: 2026-08-27 | V9: 2026년 원문 p76~79 대조 완료 / 원문 표기는 "정치식"/"기타" 2열. 규격의 "정치식(현장믹서)"는 원문상 "기타" 열
A10: CV-CON-005 | B10: 토목, 건축 | C10: 콘크리트·포장 | D10: 석분 | F10: 정치식(배치플랜트) | G10: ㎥ | H10: 2 | I10: 2 | J10: KCS-STD | K10: 1-3-1 1. 콘크리트 및 포장용 재료 | L10: 76 | M10: 2026 | O10: 석분 | R10: 기타 | S10: N | T10: 검증완료 | U10: 2026-08-27 | V10: 2026년 원문 p76~79 대조 완료 / 원문 표기는 "정치식"/"기타" 2열. 규격의 "정치식(현장믹서)"는 원문상 "기타" 열
A11: CV-CON-006 | B11: 토목, 건축 | C11: 콘크리트·포장 | D11: 혼화재 | F11: 정치식(배치플랜트) | G11: kg | H11: 2 | I11: 2 | J11: KCS-STD | K11: 1-3-1 1. 콘크리트 및 포장용 재료 | L11: 76 | M11: 2026 | O11: 혼화재 | R11: 기타 | S11: N | T11: 검증완료 | U11: 2026-08-27 | V11: 2026년 원문 p76~79 대조 완료 / 원문 표기는 "정치식"/"기타" 2열. 규격의 "정치식(현장믹서)"는 원문상 "기타" 열
A12: CV-CON-007 | B12: 토목, 건축 | C12: 콘크리트·포장 | D12: 시멘트 | F12: 정치식(현장믹서) | G12: kg | H12: 3 | I12: 3 | J12: KCS-STD | K12: 1-3-1 1. 콘크리트 및 포장용 재료 | L12: 76 | M12: 2026 | O12: 시멘트 | R12: 주요 | S12: N | T12: 검증완료 | U12: 2026-08-27 | V12: 2026년 원문 p76~79 대조 완료 / 원문 표기는 "정치식"/"기타" 2열. 규격의 "정치식(현장믹서)"는 원문상 "기타" 열
A13: CV-CON-008 | B13: 토목, 건축 | C13: 콘크리트·포장 | D13: 잔골재, 채움재 | F13: 정치식(현장믹서) | G13: ㎥ | H13: 12 | I13: 12 | J13: KCS-STD | K13: 1-3-1 1. 콘크리트 및 포장용 재료 | L13: 76 | M13: 2026 | O13: 잔골재, 채움재 | R13: 기타 | S13: N | T13: 검증완료 | U13: 2026-08-27 | V13: 2026년 원문 p76~79 대조 완료 / 원문 표기는 "정치식"/"기타" 2열. 규격의 "정치식(현장믹서)"는 원문상 "기타" 열
A14: CV-CON-009 | B14: 토목, 건축 | C14: 콘크리트·포장 | D14: 굵은골재 | F14: 정치식(현장믹서) | G14: ㎥ | H14: 5 | I14: 5 | J14: KCS-STD | K14: 1-3-1 1. 콘크리트 및 포장용 재료 | L14: 76 | M14: 2026 | O14: 굵은골재 | R14: 기타 | S14: N | T14: 검증완료 | U14: 2026-08-27 | V14: 2026년 원문 p76~79 대조 완료 / 원문 표기는 "정치식"/"기타" 2열. 규격의 "정치식(현장믹서)"는 원문상 "기타" 열
A15: CV-CON-010 | B15: 토목, 건축 | C15: 콘크리트·포장 | D15: 아스팔트 | F15: 정치식(현장믹서) | G15: ton | H15: 3 | I15: 3 | J15: KCS-STD | K15: 1-3-1 1. 콘크리트 및 포장용 재료 | L15: 76 | M15: 2026 | O15: 아스팔트 | R15: 주요 | S15: N | T15: 검증완료 | U15: 2026-08-27 | V15: 2026년 원문 p76~79 대조 완료 / 원문 표기는 "정치식"/"기타" 2열. 규격의 "정치식(현장믹서)"는 원문상 "기타" 열
A16: CV-CON-011 | B16: 토목, 건축 | C16: 콘크리트·포장 | D16: 석분 | F16: 정치식(현장믹서) | G16: ㎥ | H16: 3 | I16: 3 | J16: KCS-STD | K16: 1-3-1 1. 콘크리트 및 포장용 재료 | L16: 76 | M16: 2026 | O16: 석분 | R16: 기타 | S16: N | T16: 검증완료 | U16: 2026-08-27 | V16: 2026년 원문 p76~79 대조 완료 / 원문 표기는 "정치식"/"기타" 2열. 규격의 "정치식(현장믹서)"는 원문상 "기타" 열
... A23: CV-PIP-001 | B23: 토목 | C23: 관·구조물기초 | D23: 모래 | F23: 관 및 구조물기초 부설재료 | G23: ㎥ | H23: 4 | I23: 4 | J23: KCS-STD | K23: 1-3-1 3. 관 및 구조물기초 부설재료 | L23: 76 | M23: 2026 | O23: 모래 | R23: 주요 | S23: N | T23: 검증완료 | U23: 2026-08-27 | V23: 2026년 원문 p76~79 대조 완료
A24: CV-SOL-001 | B24: 토목 | C24: 토사(해상) | D24: 치환모래 | F24: 토사(해상) | G24: ㎥ | H24: 20 | I24: 20 | J24: KCS-STD | K24: 1-3-1 4. 토사(해상) | L24: 76 | M24: 2026 | O24: 치환모래 | P24: 표면건조포화상태의 모래에 대한 할증률 | R24: 기타 | S24: N | T24: 검증완료 | U24: 2026-08-27 | V24: 2026년 원문 p76~79 대조 완료
A25: CV-SOL-002 | B25: 토목 | C25: 토사(해상) | D25: 깔모래 | F25: 토사(해상) | G25: ㎥ | H25: 30 | I25: 30 | J25: KCS-STD | K25: 1-3-1 4. 토사(해상) | L25: 76 | M25: 2026 | O25: 깔모래 | P25: 표면건조포화상태의 모래에 대한 할증률 | R25: 기타 | S25: N | T25: 검증완료 | U25: 2026-08-27 | V25: 2026년 원문 p76~79 대조 완료
A26: CV-SOL-003 | B26: 토목 | C26: 토사(해상) | D26: 사항용모래 | F26: 토사(해상) | G26: ㎥ | H26: 20 | I26: 20 | J26: KCS-STD | K26: 1-3-1 4. 토사(해상) | L26: 76 | M26: 2026 | O26: 사항용모래 | P26: 표면건조포화상태의 모래에 대한 할증률 | R26: 기타 | S26: N | T26: 검증완료 | U26: 2026-08-27 | V26: 2026년 원문 p76~79 대조 완료
A27: CV-SOL-004 | B27: 토목 | C27: 토사(해상) | D27: 압입모래 | F27: 토사(해상) | G27: ㎥ | H27: 40 | I27: 40 | J27: KCS-STD | K27: 1-3-1 4. 토사(해상) | L27: 76 | M27: 2026 | O27: 압입모래(壓入砂) | R27: 기타 | S27: N | T27: 검증완료 | U27: 2026-08-27 | V27: 2026년 원문 p76~79 대조 완료 / 품명 정정: 압밀모래 → 압입모래(壓入砂)
A28: CV-RIP-001 | B28: 토목 | C28: 사석(해상) | D28: 기초사석 | F28: 보통지반(2m이상) | G28: ㎥ | H28: 20 | I28: 20 | J28: KCS-STD | K28: 1-3-1 5. 사석(해상) | L28: 76 | M28: 2026 | O28: 일반적으로 사용 | P28: 공사위치·자연조건·제체규모 등 현장조건에 맞게 적용 가능(원문 [주]) | R28: 주요 | S28: N | T28: 검증완료 | U28: 2026-08-27 | V28: 2026년 원문 p76~79 대조 완료
A29: CV-RIP-002 | B29: 토목 | C29: 사석(해상) | D29: 피복석 | F29: 보통지반(2m이상) | G29: ㎥ | H29: 15 | I29: 15 | J29: KCS-STD | K29: 1-3-1 5. 사석(해상) | L29: 76 | M29: 2026 | O29: 일반적으로 사용 | P29: 공사위치·자연조건·제체규모 등 현장조건에 맞게 적용 가능(원문 [주]) | R29: 주요 | S29: N | T29: 검증완료 | U29: 2026-08-27 | V29: 2026년 원문 p76~79 대조 완료
A30: CV-RIP-003 | B30: 토목 | C30: 사석(해상) | D30: 뒤채움사석 | F30: 보통지반(2m이상) | G30: ㎥ | H30: 20 | I30: 20 | J30: KCS-STD | K30: 1-3-1 5. 사석(해상) | L30: 76 | M30: 2026 | O30: 일반적으로 사용 | P30: 공사위치·자연조건·제체규모 등 현장조건에 맞게 적용 가능(원문 [주]) | R30: 주요 | S30: N | T30: 검증완료 | U30: 2026-08-27 | V30: 2026년 원문 p76~79 대조 완료
A31: CV-RIP-004 | B31: 토목 | C31: 사석(해상) | D31: 기초사석 | E31: 3 | F31: 보통지반(2m미만) | G31: ㎥ | H31: 25 | I31: 25 | J31: KCS-STD | K31: 1-3-1 5. 사석(해상) | L31: 76 | M31: 2026 | O31: 특별한경우 협의하여 사용 | P31: 공사위치·자연조건·제체규모 등 현장조건에 맞게 적용 가능(원문 [주]) | R31: 기타 | S31: N | T31: 검증완료 | U31: 2026-08-27 | V31: 2026년 원문 p76~79 대조 완료
A32: CV-RIP-005 | B32: 토목 | C32: 사석(해상) | D32: 피복석 | E32: 4 | F32: 보통지반(2m미만) | G32: ㎥ | H32: 15 | I32: 15 | J32: KCS-STD | K32: 1-3-1 5. 사석(해상) | L32: 76 | M32: 2026 | O32: 특별한경우 협의하여 사용 | P32: 공사위치·자연조건·제체규모 등 현장조건에 맞게 적용 가능(원문 [주]) | R32: 기타 | S32: N | T32: 검증완료 | U32: 2026-08-27 | V32: 2026년 원문 p76~79 대조 완료
A33: CV-RIP-006 | B33: 토목 | C33: 사석(해상) | D33: 뒤채움사석 | E33: 5 | F33: 보통지반(2m미만) | G33: ㎥ | H33: 20 | I33: 20 | J33: KCS-STD | K33: 1-3-1 5. 사석(해상) | L33: 76 | M33: 2026 | O33: 특별한경우 협의하여 사용 | P33: 공사위치·자연조건·제체규모 등 현장조건에 맞게 적용 가능(원문 [주]) | R33: 기타 | S33: N | T33: 검증완료 | U33: 2026-08-27 | V33: 2026년 원문 p76~79 대조 완료
A34: CV-RIP-007 | B34: 토목 | C34: 사석(해상) | D34: 기초사석 | F34: 모래치환지반(2m이상) | G34: ㎥ | H34: 25 | I34: 25 | J34: KCS-STD | K34: 1-3-1 5. 사석(해상) | L34: 76 | M34: 2026 | O34: 특별한경우 협의하여 사용 | P34: 공사위치·자연조건·제체규모 등 현장조건에 맞게 적용 가능(원문 [주]) | R34: 기타 | S34: N | T34: 검증완료 | U34: 2026-08-27 | V34: 2026년 원문 p76~79 대조 완료
A35: CV-RIP-008 | B35: 토목 | C35: 사석(해상) | D35: 피복석 | F35: 모래치환지반(2m이상) | G35: ㎥ | H35: 15 | I35: 15 | J35: KCS-STD | K35: 1-3-1 5. 사석(해상) | L35: 76 | M35: 2026 | O35: 특별한경우 협의하여 사용 | P35: 공사위치·자연조건·제체규모 등 현장조건에 맞게 적용 가능(원문 [주]) | R35: 기타 | S35: N | T35: 검증완료 | U35: 2026-08-27 | V35: 2026년 원문 p76~79 대조 완료
A36: CV-RIP-009 | B36: 토목 | C36: 사석(해상) | D36: 뒤채움사석 | F36: 모래치환지반(2m이상) | G36: ㎥ | H36: 20 | I36: 20 | J36: KCS-STD | K36: 1-3-1 5. 사석(해상) | L36: 76 | M36: 2026 | O36: 특별한경우 협의하여 사용 | P36: 공사위치·자연조건·제체규모 등 현장조건에 맞게 적용 가능(원문 [주]) | R36: 기타 | S36: N | T36: 검증완료 | U36: 2026-08-27 | V36: 2026년 원문 p76~79 대조 완료
A37: CV-RIP-010 | B37: 토목 | C37: 사석(해상) | D37: 기초사석 | F37: 모래치환지반(2m미만) | G37: ㎥ | H37: 30 | I37: 30 | J37: KCS-STD | K37: 1-3-1 5. 사석(해상) | L37: 76 | M37: 2026 | O37: 특별한경우 협의하여 사용 | P37: 공사위치·자연조건·제체규모 등 현장조건에 맞게 적용 가능(원문 [주]) | R37: 기타 | S37: N | T37: 검증완료 | U37: 2026-08-27 | V37: 2026년 원문 p76~79 대조 완료
A38: CV-RIP-011 | B38: 토목 | C38: 사석(해상) | D38: 피복석 | F38: 모래치환지반(2m미만) | G38: ㎥ | H38: 15 | I38: 15 | J38: KCS-STD | K38: 1-3-1 5. 사석(해상) | L38: 76 | M38: 2026 | O38: 특별한경우 협의하여 사용 | P38: 공사위치·자연조건·제체규모 등 현장조건에 맞게 적용 가능(원문 [주]) | R38: 기타 | S38: N | T38: 검증완료 | U38: 2026-08-27 | V38: 2026년 원문 p76~79 대조 완료
A39: CV-RIP-012 | B39: 토목 | C39: 사석(해상) | D39: 뒤채움사석 | F39: 모래치환지반(2m미만) | G39: ㎥ | H39: 20 | I39: 20 | J39: KCS-STD | K39: 1-3-1 5. 사석(해상) | L39: 76 | M39: 2026 | O39: 특별한경우 협의하여 사용 | P39: 공사위치·자연조건·제체규모 등 현장조건에 맞게 적용 가능(원문 [주]) | R39: 기타 | S39: N | T39: 검증완료 | U39: 2026-08-27 | V39: 2026년 원문 p76~79 대조 완료
A40: CV-RIP-013 | B40: 토목 | C40: 사석(해상) | D40: 기초사석 | F40: 연약지반(2m이상) | G40: ㎥ | H40: 40 | I40: 40 | J40: KCS-STD | K40: 1-3-1 5. 사석(해상) | L40: 76 | M40: 2026 | O40: 특별한경우 협의하여 사용 | P40: 공사위치·자연조건·제체규모 등 현장조건에 맞게 적용 가능(원문 [주]) | R40: 기타 | S40: N | T40: 검증완료 | U40: 2026-08-27 | V40: 2026년 원문 p76~79 대조 완료
A41: CV-RIP-014 | B41: 토목 | C41: 사석(해상) | D41: 피복석 | F41: 연약지반(2m이상) | G41: ㎥ | H41: 20 | I41: 20 | J41: KCS-STD | K41: 1-3-1 5. 사석(해상) | L41: 76 | M41: 2026 | O41: 특별한경우 협의하여 사용 | P41: 공사위치·자연조건·제체규모 등 현장조건에 맞게 적용 가능(원문 [주]) | R41: 기타 | S41: N | T41: 검증완료 | U41: 2026-08-27 | V41: 2026년 원문 p76~79 대조 완료
A42: CV-RIP-015 | B42: 토목 | C42: 사석(해상) | D42: 뒤채움사석 | F42: 연약지반(2m이상) | G42: ㎥ | H42: 25 | I42: 25 | J42: KCS-STD | K42: 1-3-1 5. 사석(해상) | L42: 76 | M42: 2026 | O42: 특별한경우 협의하여 사용 | P42: 공사위치·자연조건·제체규모 등 현장조건에 맞게 적용 가능(원문 [주]) | R42: 기타 | S42: N | T42: 검증완료 | U42: 2026-08-27 | V42: 2026년 원문 p76~79 대조 완료
A43: CV-RIP-016 | B43: 토목 | C43: 사석(해상) | D43: 기초사석 | F43: 연약지반(2m미만) | G43: ㎥ | H43: 50 | I43: 50 | J43: KCS-STD | K43: 1-3-1 5. 사석(해상) | L43: 76 | M43: 2026 | O43: 특별한경우 협의하여 사용 | P43: 공사위치·자연조건·제체규모 등 현장조건에 맞게 적용 가능(원문 [주]) | R43: 기타 | S43: N | T43: 검증완료 | U43: 2026-08-27 | V43: 2026년 원문 p76~79 대조 완료
A44: CV-RIP-017 | B44: 토목 | C44: 사석(해상) | D44: 피복석 | F44: 연약지반(2m미만) | G44: ㎥ | H44: 20 | I44: 20 | J44: KCS-STD | K44: 1-3-1 5. 사석(해상) | L44: 76 | M44: 2026 | O44: 특별한경우 협의하여 사용 | P44: 공사위치·자연조건·제체규모 등 현장조건에 맞게 적용 가능(원문 [주]) | R44: 기타 | S44: N | T44: 검증완료 | U44: 2026-08-27 | V44: 2026년 원문 p76~79 대조 완료
A45: CV-RIP-018 | B45: 토목 | C45: 사석(해상) | D45: 뒤채움사석 | F45: 연약지반(2m미만) | G45: ㎥ | H45: 25 | I45: 25 | J45: KCS-STD | K45: 1-3-1 5. 사석(해상) | L45: 76 | M45: 2026 | O45: 특별한경우 협의하여 사용 | P45: 공사위치·자연조건·제체규모 등 현장조건에 맞게 적용 가능(원문 [주]) | R45: 기타 | S45: N | T45: 검증완료 | U45: 2026-08-27 | V45: 2026년 원문 p76~79 대조 완료
A46: CV-FIL-001 | B46: 토목 | C46: 속채움(해상) | D46: 모래 | F46: 속채움(해상) | G46: ㎥ | H46: 10 | I46: 10 | J46: KCS-STD | K46: 1-3-1 6. 속채움(해상) | L46: 77 | M46: 2026 | O46: 케이슨 또는 블록등의 속채움시 콘크리트 속채움재는 제외 | R46: 주요 | S46: N | T46: 검증완료 | U46: 2026-08-27 | V46: 2026년 원문 p76~79 대조 완료
...

Sheet 출처
A1: 출처코드 | B1: 출처명 | C1: 발행기관 | D1: 대상공종 | E1: 개정주기 | F1: 원문위치 | G1: 원문링크 | H1: 파일명(→원문파일 시트) | I1: 수록판 | J1: 확인일 | K1: 상태
A2: KCS-STD | B2: 건설공사 표준품셈 | C2: 국토교통부 · 한국건설기술연구원 | D2: 토목, 건축 | E2: 연 1회(12월말 공고) | F2: CODIL > 건설기준정보 > 품셈·표준시장단가 | G2: https://www.codil.or.kr/helpdesk/search.do?bbsId=BBSMSTR_900000000202&bbsAttrbCode=BBSA01 | I2: 2026년 상반기 | J2: 2026-08-27 | K2: 사용중
A3: NHR-PRC | B3: 국도건설공사 설계실무요령 | C3: 국토교통부 | D3: 토목 | E3: 비정기 | F3: 국토교통부 발간자료 | G3: https://www.molit.go.kr/USR/policyData/m_34681/dtl.jsp?id=4896 | I3: 2025.06 | J3: 2026-08-27 | K3: 사용중
A4: ELE-STD | B4: 전기공사 표준품셈 | C4: 대한전기협회 | D4: 전기 | E4: 연 1회 | F4: 대한전기협회 표준품셈 | G4: https://sec.kea.kr | K4: 확장예정
A5: ICT-STD | B5: 정보통신공사 표준품셈 | C5: 한국정보통신산업연구원 | D5: 정보통신 | E5: 연 1회 | F5: 공공데이터포털 파일데이터 | G5: https://www.data.go.kr/data/15059957/fileData.do | K5: 확장예정
A6: ETC-KDS | B6: KDS·KCS 설계기준·표준시방서 | C6: 국가건설기준센터 | D6: 기타 | E6: 수시 | F6: 국가건설기준센터 | G6: https://www.kcsc.re.kr | K6: 확장예정
A7: LH-CIV | B7: LH 설계지침(토목) | C7: 한국토지주택공사 | D7: 토목 | E7: 비정기(차수 개정) | F7: LH 설계기준 · 지침 | G7: https://lh.or.kr/search.es?mid=a10813010000&allKeyWord=%EC%84%A4%EA%B3%84%EC%A7%80%EC%B9%A8 | I7: 2026.04 개정(45차 이후) | J7: 2026-08-27 | K7: 사용중

Sheet 원문파일
A1: 출처코드 | B1: 적용연도 | C1: 판 | D1: 파일명 | E1: 쪽수 | F1: 원문링크 | G1: 상태
A2: KCS-STD | B2: 2024 | C2: 2024년 적용 | D2: 2024년_건설공사_표준품셈.pdf | E2: 937 | F2: https://www.codil.or.kr/helpdesk/search.do?bbsId=BBSMSTR_900000000202&bbsAttrbCode=BBSA01 | G2: 과년도
A3: KCS-STD | B3: 2025 | C3: 2025년 적용 | D3: 2025년_건설공사_표준품셈.pdf | E3: 947 | F3: https://www.codil.or.kr/helpdesk/search.do?bbsId=BBSMSTR_900000000202&bbsAttrbCode=BBSA01 | G3: 과년도
A4: KCS-STD | B4: 2026 | C4: 2026년 적용 | D4: 2026년_건설공사_표준품셈.pdf | E4: 982 | F4: https://www.codil.or.kr/helpdesk/search.do?bbsId=BBSMSTR_900000000202&bbsAttrbCode=BBSA01 | G4: 현행
A5: NHR-PRC | B5: 2025 | C5: 2025.06.12 | D5: 250612_국도건설공사_설계실무_요령.pdf | E5: 1399 | F5: https://www.molit.go.kr/USR/policyData/m_34681/dtl.jsp?id=4896 | G5: 현행
A6: LH-CIV | B6: 2025 | C6: 제3454호(2025.11.26. 45차 개정) | D6: LH설계지침토목-2025_11.pdf | E6: 307 | F6: https://lh.or.kr/search.es?mid=a10813010000&allKeyWord=%EC%84%A4%EA%B3%84%EC%A7%80%EC%B9%A8 | G6: 과년도
A7: LH-CIV | B7: 2026 | C7: 2026.04 개정 | D7: LH설계지침토목-2026_04.pdf | E7: 304 | F7: https://lh.or.kr/search.es?mid=a10813010000&allKeyWord=%EC%84%A4%EA%B3%84%EC%A7%80%EC%B9%A8 | G7: 현행

Sheet 현황
A1: 데이터 현황 (DB 시트 자동 집계)
A3: 공종별
A4: 공종 | B4: 검증완료 | C4: 초안
A5: 토목 | B5: =SUMPRODUCT(ISNUMBER(SEARCH("토목",DB!$B$2:$B$498))*(DB!$T$2:$T$498="검증완료")) -> 267 | C5: =SUMPRODUCT(ISNUMBER(SEARCH("토목",DB!$B$2:$B$498))*(DB!$T$2:$T$498="초안")) -> 0
A6: 건축 | B6: =SUMPRODUCT(ISNUMBER(SEARCH("건축",DB!$B$2:$B$498))*(DB!$T$2:$T$498="검증완료")) -> 86 | C6: =SUMPRODUCT(ISNUMBER(SEARCH("건축",DB!$B$2:$B$498))*(DB!$T$2:$T$498="초안")) -> 0
A7: 전기 | B7: =SUMPRODUCT(ISNUMBER(SEARCH("전기",DB!$B$2:$B$498))*(DB!$T$2:$T$498="검증완료")) -> 0 | C7: =SUMPRODUCT(ISNUMBER(SEARCH("전기",DB!$B$2:$B$498))*(DB!$T$2:$T$498="초안")) -> 0
A8: 정보통신 | B8: =SUMPRODUCT(ISNUMBER(SEARCH("정보통신",DB!$B$2:$B$498))*(DB!$T$2:$T$498="검증완료")) -> 0 | C8: =SUMPRODUCT(ISNUMBER(SEARCH("정보통신",DB!$B$2:$B$498))*(DB!$T$2:$T$498="초안")) -> 0
A9: 기타 | B9: =SUMPRODUCT(ISNUMBER(SEARCH("기타",DB!$B$2:$B$498))*(DB!$T$2:$T$498="검증완료")) -> 0 | C9: =SUMPRODUCT(ISNUMBER(SEARCH("기타",DB!$B$2:$B$498))*(DB!$T$2:$T$498="초안")) -> 0
A11: 분류별
A12: 분류 | B12: 건수
A13: 콘크리트·포장 | B13: =COUNTIF(DB!$C$2:$C$498,A13) -> 35
A14: 노상·노반 | B14: =COUNTIF(DB!$C$2:$C$498,A14) -> 16
A15: 관·구조물기초 | B15: =COUNTIF(DB!$C$2:$C$498,A15) -> 3
A16: 토사(해상) | B16: =COUNTIF(DB!$C$2:$C$498,A16) -> 4
A17: 사석(해상) | B17: =COUNTIF(DB!$C$2:$C$498,A17) -> 18
A18: 속채움(해상) | B18: =COUNTIF(DB!$C$2:$C$498,A18) -> 2
A19: 강재류 | B19: =COUNTIF(DB!$C$2:$C$498,A19) -> 43
A20: 기타재료 | B20: =COUNTIF(DB!$C$2:$C$498,A20) -> 143
A21: 토공 | B21: =COUNTIF(DB!$C$2:$C$498,A21) -> 3
A23: 합계 | B23: =COUNTA(DB!$A$2:$A$498) -> 267
A25: 태그 입력된 행 | B25: =COUNTIF(DB!$Q$2:$Q$498,"?*") -> 78
A26: 적용종료가 기입된 행(과년도) | B26: =COUNT(DB!$N$2:$N$498) -> 0
A27: 원문페이지가 기입된 행 | B27: =COUNT(DB!$L$2:$L$498) -> 266

Sheet 안내
A1: 재료 할증률 마스터 — 작업 규칙
A3: 이 파일이 원본입니다 | B3: DB 시트만 고치면 convert.py가 data.json을 만들고 사이트가 갱신됩니다. 사이트 코드는 건드리지 않습니다.
A5: ① 항목을 추가할 때 | B5: DB 시트 마지막에 행 추가 → ID는 CV-분류코드-순번(중복 금지) → 상태는 작업 중이면 "초안"(사이트에 안 나옴), 끝나면 "검증완료".
A6: ② 기준값이 바뀌었을 때 | B6: 기존 행의 적용종료에 직전 연도를 넣고, 같은 ID로 새 행을 추가해 적용시작에 새 연도를 넣습니다. 값을 덮어쓰지 마세요.
A7: ③ 오타를 고칠 때 | B7: 그냥 덮어씁니다. 기준 변경이 아니므로 이력을 남기지 않습니다.
A8: ④ 공종을 넓힐 때 | B8: 출처 시트에서 해당 출처의 상태를 "사용중"으로 바꾸고, DB 시트에 그 출처코드로 행을 추가합니다. ID 접두는 EL/IC/ET.
A10: 공종 배정 기준(현재) | B10: 해상·도로 전용 조항(토사·사석·속채움·노상노반·관기초)은 토목 전용, 표준품셈 공통편(콘크리트·강재류·기타재료)은 토목·건축 공통으로 넣어 두었습니다. 실무와 다르면 B열에서 바로 고치세요.
A11: 원문 보기 · 내려받기 | B11: CODIL에서 PDF를 받아 사이트 옆 docs/ 폴더에 넣고 python find_page.py 를 실행하면 원문페이지 열이 채워지고, 카드의 “원문 보기”가 해당 쪽으로 바로 엽니다. PDF는 재배포하지 말고 각자 내려받아 쓰세요.
A12: 적용연도 현황 | B12: 현재 94건 모두 적용시작 2026 · 적용종료 공란입니다. 2024·2025년 원문을 확보하면 그 값으로 과년도 행을 추가하세요.
A14: 예시 행 (형식 참고용, DB 시트에는 넣지 마세요)
A15: ID | B15: 공종 | C15: 분류 | D15: 품명 | E15: 규격 | F15: 단위 | G15: 할증_min | H15: 할증_max | I15: 출처코드 | J15: 조항위치 | K15: 원문페이지 | L15: 적용시작 | M15: 적용종료 | N15: 정식명칭 | O15: 비고 | P15: 태그 | Q15: 중요도 | R15: 올림적용 | S15: 상태 | T15: 수정일 | U15: 검증메모
A16: CV-STL-999 | B16: 토목, 건축 | C16: 강재류 | D16: 이형철근 | E16: 일반적용 | F16: ton | G16: 3 | H16: 3 | I16: KCS-STD | J16: 1-3-1 7. 강재류 | K16: 61 | L16: 2026 | N16: 할증율은 현장여건을 반영하여 조절하여 사용가능 | P16: 철근, rebar, 이형 | Q16: 주요 | R16: N | S16: 검증완료 | T16: 2026-08-27 | U16: 예시
